--------------------
Failed to process https://github.com/30-seconds/30-seconds-of-code.git repo
Traceback (most recent call last):
  File "/style-analyzer/lookout/style/format/benchmarks/quality_report.py", line 312, in generate_quality_report
    vnodes_expected_number=vnodes_expected_number)
  File "/style-analyzer/lookout/style/format/benchmarks/quality_report.py", line 135, in measure_quality
    (restarts, repository))
RuntimeError: Run out of 3 attempts. Failed to train proper model for https://github.com/30-seconds/30-seconds-of-code.git.
--------------------
Failed to process https://github.com/expressjs/express.git repo
Traceback (most recent call last):
  File "/style-analyzer/lookout/style/format/benchmarks/quality_report.py", line 312, in generate_quality_report
    vnodes_expected_number=vnodes_expected_number)
  File "/style-analyzer/lookout/style/format/benchmarks/quality_report.py", line 137, in measure_quality
    bblfsh=bblfsh, config_json=config)
  File "/lookout-sdk-ml/lookout/core/helpers/analyzer_context_manager.py", line 87, in review
    log_level=log_level, config_json=config_json)
  File "/lookout-sdk-ml/lookout/core/helpers/server.py", line 101, in review
    return self._run("review", fr, to, port, git_dir, bblfsh, log_level, config_json)
  File "/lookout-sdk-ml/lookout/core/helpers/server.py", line 131, in _run
    return subprocess.run(command, stdout=subprocess.PIPE, stderr=subprocess.PIPE, check=True)
  File "/usr/lib/python3.6/subprocess.py", line 418, in run
    output=stdout, stderr=stderr)
subprocess.CalledProcessError: Command '['/tmp/lookout-sdk-ml/lookout-sdk-v0.7.0', 'review', 'ipv4://localhost:22859', '--from', '8fe5fd89c6392c055bf9a05b7f0fe855b264a91d', '--to', '06d11755c99fe4c1cddf8b889a687448b568472d', '--git-dir', '/tmp/top-repos-quality-repos-95jp8mls/express.git', '--log-format', 'json', '--log-level', 'warning', '--config-json', '{"style.format.analyzer.FormatAnalyzer": {"aggregate": true}}']' returned non-zero exit status 1.
--------------------
Failed to process https://github.com/atom/atom.git repo
Traceback (most recent call last):
  File "/style-analyzer/lookout/style/format/benchmarks/quality_report.py", line 312, in generate_quality_report
    vnodes_expected_number=vnodes_expected_number)
  File "/style-analyzer/lookout/style/format/benchmarks/quality_report.py", line 135, in measure_quality
    (restarts, repository))
RuntimeError: Run out of 3 attempts. Failed to train proper model for https://github.com/atom/atom.git.
--------------------
Failed to process https://github.com/freecodecamp/freecodecamp.git repo
Traceback (most recent call last):
  File "/style-analyzer/lookout/style/format/benchmarks/quality_report.py", line 312, in generate_quality_report
    vnodes_expected_number=vnodes_expected_number)
  File "/style-analyzer/lookout/style/format/benchmarks/quality_report.py", line 137, in measure_quality
    bblfsh=bblfsh, config_json=config)
  File "/lookout-sdk-ml/lookout/core/helpers/analyzer_context_manager.py", line 87, in review
    log_level=log_level, config_json=config_json)
  File "/lookout-sdk-ml/lookout/core/helpers/server.py", line 101, in review
    return self._run("review", fr, to, port, git_dir, bblfsh, log_level, config_json)
  File "/lookout-sdk-ml/lookout/core/helpers/server.py", line 131, in _run
    return subprocess.run(command, stdout=subprocess.PIPE, stderr=subprocess.PIPE, check=True)
  File "/usr/lib/python3.6/subprocess.py", line 418, in run
    output=stdout, stderr=stderr)
subprocess.CalledProcessError: Command '['/tmp/lookout-sdk-ml/lookout-sdk-v0.7.0', 'review', 'ipv4://localhost:22859', '--from', 'e9614d60d4383b74fbc249b3920c6653a158bc05', '--to', 'f8aa621672fbe7d81e551ab2a54e924907a6cc9f', '--git-dir', '/tmp/top-repos-quality-repos-sne7mi9r/freecodecamp.git', '--log-format', 'json', '--log-level', 'warning', '--config-json', '{"style.format.analyzer.FormatAnalyzer": {"aggregate": true}}']' returned non-zero exit status 1.
